<?xml version="1.0" ?>
<robot name="medibotv4" xmlns:xacro="http://www.ros.org/wiki/xacro">

<xacro:include filename="$(find medibotv4_description)/urdf/materials.xacro" />
<xacro:include filename="$(find medibotv4_description)/urdf/medibotv4.trans" />
<xacro:include filename="$(find medibotv4_description)/gazebo/medibotv4_materials.gazebo" />
<xacro:include filename="$(find medibotv4_description)/gazebo/medibotv4_physics.gazebo" />
<xacro:include filename="$(find medibotv4_description)/gazebo/medibotv4_plugins.gazebo" />

<link name="base_link">
  <inertial>
    <origin rpy="0 0 0" xyz="0.025297764443169172 3.0256355552437136e-17 0.18296685961651218"/>
    <mass value="12.985758"/>
    <inertia ixx="0.501298" ixy="0.0" ixz="0.050215" iyy="0.524336" iyz="0.0" izz="0.640713"/>
  </inertial>
  <visual>
    <origin rpy="0 0 0" xyz="0 0 0"/>
    <geometry>
      <mesh filename="package://medibotv4_description/meshes/base_link.stl" scale="0.001 0.001 0.001"/>
    </geometry>
    <material name="silver"/>
  </visual>
  <collision>
    <origin rpy="0 0 0" xyz="0 0 0"/>
    <geometry>
      <mesh filename="package://medibotv4_description/meshes/base_link.stl" scale="0.001 0.001 0.001"/>
    </geometry>
  </collision>
</link>

<link name="left_motor_1">
  <inertial>
    <origin rpy="0 0 0" xyz="0.016444563411155556 0.06191343975327798 -0.056741856887104675"/>
    <mass value="14.646460109710683"/>
    <inertia ixx="0.057727" ixy="-0.012462" ixz="-0.001235" iyy="0.065718" iyz="-0.001816" izz="0.065303"/>
  </inertial>
  <visual>
    <origin rpy="0 0 0" xyz="0.0535 -0.1535 -0.2145"/>
    <geometry>
      <mesh filename="package://medibotv4_description/meshes/left_motor_1.stl" scale="0.001 0.001 0.001"/>
    </geometry>
    <material name="silver"/>
  </visual>
  <collision>
    <origin rpy="0 0 0" xyz="0.0535 -0.1535 -0.2145"/>
    <geometry>
      <mesh filename="package://medibotv4_description/meshes/left_motor_1.stl" scale="0.001 0.001 0.001"/>
    </geometry>
  </collision>
</link>

<link name="right_motor_1">
  <inertial>
    <origin rpy="0 0 0" xyz="0.016260474645192965 -0.06154741876400091 -0.05676908795148311"/>
    <mass value="14.61528122194152"/>
    <inertia ixx="0.057597" ixy="0.012516" ixz="-0.00123" iyy="0.065274" iyz="0.001804" izz="0.065194"/>
  </inertial>
  <visual>
    <origin rpy="0 0 0" xyz="0.0535 0.1535 -0.2145"/>
    <geometry>
      <mesh filename="package://medibotv4_description/meshes/right_motor_1.stl" scale="0.001 0.001 0.001"/>
    </geometry>
    <material name="silver"/>
  </visual>
  <collision>
    <origin rpy="0 0 0" xyz="0.0535 0.1535 -0.2145"/>
    <geometry>
      <mesh filename="package://medibotv4_description/meshes/right_motor_1.stl" scale="0.001 0.001 0.001"/>
    </geometry>
  </collision>
</link>

<link name="left_wheel_1">
  <inertial>
    <origin rpy="0 0 0" xyz="7.953816428402094e-09 -0.030000265793469483 4.539531719971457e-08"/>
    <mass value="2.266879326854612"/>
    <inertia ixx="0.021472" ixy="-0.0" ixz="0.0" iyy="0.041643" iyz="-0.0" izz="0.021472"/>
  </inertial>
  <visual>
    <origin rpy="0 0 0" xyz="0.0175 -0.279 -0.16"/>
    <geometry>
      <mesh filename="package://medibotv4_description/meshes/left_wheel_1.stl" scale="0.001 0.001 0.001"/>
    </geometry>
    <material name="silver"/>
  </visual>
  <collision>
    <origin rpy="0 0 0" xyz="0.0175 -0.279 -0.16"/>
    <geometry>
      <mesh filename="package://medibotv4_description/meshes/left_wheel_1.stl" scale="0.001 0.001 0.001"/>
    </geometry>
  </collision>
</link>

<link name="right_wheel_1">
  <inertial>
    <origin rpy="0 0 0" xyz="7.952848390252454e-09 0.030000265792822806 -4.540530937346965e-08"/>
    <mass value="2.266879326854595"/>
    <inertia ixx="0.021472" ixy="0.0" ixz="-0.0" iyy="0.041643" iyz="-0.0" izz="0.021472"/>
  </inertial>
  <visual>
    <origin rpy="0 0 0" xyz="0.0175 0.279 -0.16"/>
    <geometry>
      <mesh filename="package://medibotv4_description/meshes/right_wheel_1.stl" scale="0.001 0.001 0.001"/>
    </geometry>
    <material name="silver"/>
  </visual>
  <collision>
    <origin rpy="0 0 0" xyz="0.0175 0.279 -0.16"/>
    <geometry>
      <mesh filename="package://medibotv4_description/meshes/right_wheel_1.stl" scale="0.001 0.001 0.001"/>
    </geometry>
  </collision>
</link>

<link name="bottom_panel_1">
  <inertial>
    <origin rpy="0 0 0" xyz="0.023521505376344086 0.195 0.0025000000000000022"/>
    <mass value="0.994356"/>
    <inertia ixx="0.01116" ixy="0.0" ixz="-0.0" iyy="0.017329" iyz="0.0" izz="0.028485"/>
  </inertial>
  <visual>
    <origin rpy="0 0 0" xyz="-0.0 0.195 -0.06"/>
    <geometry>
      <mesh filename="package://medibotv4_description/meshes/bottom_panel_1.stl" scale="0.001 0.001 0.001"/>
    </geometry>
    <material name="silver"/>
  </visual>
  <collision>
    <origin rpy="0 0 0" xyz="-0.0 0.195 -0.06"/>
    <geometry>
      <mesh filename="package://medibotv4_description/meshes/bottom_panel_1.stl" scale="0.001 0.001 0.001"/>
    </geometry>
  </collision>
</link>

<link name="circuit_panel_1">
  <inertial>
    <origin rpy="0 0 0" xyz="0.11000000000000001 0.0 0.0025000000000000022"/>
    <mass value="0.509652"/>
    <inertia ixx="0.006461" ixy="0.0" ixz="0.0" iyy="0.002057" iyz="0.0" izz="0.008515"/>
  </inertial>
  <visual>
    <origin rpy="0 0 0" xyz="0.2 -0.0 -0.35"/>
    <geometry>
      <mesh filename="package://medibotv4_description/meshes/circuit_panel_1.stl" scale="0.001 0.001 0.001"/>
    </geometry>
    <material name="silver"/>
  </visual>
  <collision>
    <origin rpy="0 0 0" xyz="0.2 -0.0 -0.35"/>
    <geometry>
      <mesh filename="package://medibotv4_description/meshes/circuit_panel_1.stl" scale="0.001 0.001 0.001"/>
    </geometry>
  </collision>
</link>

<link name="circuit_housing_1">
  <inertial>
    <origin rpy="0 0 0" xyz="0.11586679295026386 -4.768835044584394e-17 0.11525745568764251"/>
    <mass value="23.953970618548663"/>
    <inertia ixx="0.370761" ixy="0.0" ixz="-0.018114" iyy="0.314986" iyz="-0.0" izz="0.346648"/>
  </inertial>
  <visual>
    <origin rpy="0 0 0" xyz="0.2 -0.0 -0.355"/>
    <geometry>
      <mesh filename="package://medibotv4_description/meshes/circuit_housing_1.stl" scale="0.001 0.001 0.001"/>
    </geometry>
    <material name="silver"/>
  </visual>
  <collision>
    <origin rpy="0 0 0" xyz="0.2 -0.0 -0.355"/>
    <geometry>
      <mesh filename="package://medibotv4_description/meshes/circuit_housing_1.stl" scale="0.001 0.001 0.001"/>
    </geometry>
  </collision>
</link>

<link name="stand_1">
  <inertial>
    <origin rpy="0 0 0" xyz="-0.03 -5.005474418122885e-18 0.504332691249312"/>
    <mass value="9.811799999999998"/>
    <inertia ixx="0.832484" ixy="0.0" ixz="0.0" iyy="0.832484" iyz="0.0" izz="0.006002"/>
  </inertial>
  <visual>
    <origin rpy="0 0 0" xyz="-0.08 -0.0 -0.065"/>
    <geometry>
      <mesh filename="package://medibotv4_description/meshes/stand_1.stl" scale="0.001 0.001 0.001"/>
    </geometry>
    <material name="silver"/>
  </visual>
  <collision>
    <origin rpy="0 0 0" xyz="-0.08 -0.0 -0.065"/>
    <geometry>
      <mesh filename="package://medibotv4_description/meshes/stand_1.stl" scale="0.001 0.001 0.001"/>
    </geometry>
  </collision>
</link>

<link name="body_1">
  <inertial>
    <origin rpy="0 0 0" xyz="0.24442242538485656 1.3361487722796229e-15 0.22269634119543633"/>
    <mass value="78.65436391485291"/>
    <inertia ixx="5.513959" ixy="0.0" ixz="0.070146" iyy="4.755007" iyz="0.0" izz="7.74447"/>
  </inertial>
  <visual>
    <origin rpy="0 0 0" xyz="0.2 -0.0 -0.03"/>
    <geometry>
      <mesh filename="package://medibotv4_description/meshes/body_1.stl" scale="0.001 0.001 0.001"/>
    </geometry>
    <material name="silver"/>
  </visual>
  <collision>
    <origin rpy="0 0 0" xyz="0.2 -0.0 -0.03"/>
    <geometry>
      <mesh filename="package://medibotv4_description/meshes/body_1.stl" scale="0.001 0.001 0.001"/>
    </geometry>
  </collision>
</link>

<link name="lidar_1">
  <inertial>
    <origin rpy="0 0 0" xyz="1.9660910471896997e-07 3.067430088395322e-17 0.014762029367898416"/>
    <mass value="0.052814160089970474"/>
    <inertia ixx="9e-06" ixy="0.0" ixz="0.0" iyy="9e-06" iyz="0.0" izz="1e-05"/>
  </inertial>
  <visual>
    <origin rpy="0 0 0" xyz="-0.326625 -0.0 -0.225"/>
    <geometry>
      <mesh filename="package://medibotv4_description/meshes/lidar_1.stl" scale="0.001 0.001 0.001"/>
    </geometry>
    <material name="silver"/>
  </visual>
  <collision>
    <origin rpy="0 0 0" xyz="-0.326625 -0.0 -0.225"/>
    <geometry>
      <mesh filename="package://medibotv4_description/meshes/lidar_1.stl" scale="0.001 0.001 0.001"/>
    </geometry>
  </collision>
</link>

<link name="top_panel_1">
  <inertial>
    <origin rpy="0 0 0" xyz="-0.3000421262648231 1.8731188253870525e-07 0.0156616040392335"/>
    <mass value="32.135656783601455"/>
    <inertia ixx="0.9738" ixy="1e-06" ixz="0.00562" iyy="0.652206" iyz="0.0" izz="1.61362"/>
  </inertial>
  <visual>
    <origin rpy="0 0 0" xyz="-0.366625 0.0 -0.47"/>
    <geometry>
      <mesh filename="package://medibotv4_description/meshes/top_panel_1.stl" scale="0.001 0.001 0.001"/>
    </geometry>
    <material name="silver"/>
  </visual>
  <collision>
    <origin rpy="0 0 0" xyz="-0.366625 0.0 -0.47"/>
    <geometry>
      <mesh filename="package://medibotv4_description/meshes/top_panel_1.stl" scale="0.001 0.001 0.001"/>
    </geometry>
  </collision>
</link>

<link name="realsense_housing_1">
  <inertial>
    <origin rpy="0 0 0" xyz="-0.07373817098769747 7.951322418324285e-17 0.04233590361579864"/>
    <mass value="0.4849831679105662"/>
    <inertia ixx="0.003621" ixy="-0.0" ixz="7.1e-05" iyy="0.001194" iyz="-0.0" izz="0.003857"/>
  </inertial>
  <visual>
    <origin rpy="0 0 0" xyz="-0.171141 -0.0 -0.52"/>
    <geometry>
      <mesh filename="package://medibotv4_description/meshes/realsense_housing_1.stl" scale="0.001 0.001 0.001"/>
    </geometry>
    <material name="silver"/>
  </visual>
  <collision>
    <origin rpy="0 0 0" xyz="-0.171141 -0.0 -0.52"/>
    <geometry>
      <mesh filename="package://medibotv4_description/meshes/realsense_housing_1.stl" scale="0.001 0.001 0.001"/>
    </geometry>
  </collision>
</link>

<link name="left_realsense_1">
  <inertial>
    <origin rpy="0 0 0" xyz="0.00266926405942991 0.0011190896800006983 0.0"/>
    <mass value="0.04923710067597887"/>
    <inertia ixx="4.8e-05" ixy="1.9e-05" ixz="0.0" iyy="1.1e-05" iyz="0.0" izz="5.3e-05"/>
  </inertial>
  <visual>
    <origin rpy="0 0 0" xyz="-0.147314 -0.059696 -0.56"/>
    <geometry>
      <mesh filename="package://medibotv4_description/meshes/left_realsense_1.stl" scale="0.001 0.001 0.001"/>
    </geometry>
    <material name="silver"/>
  </visual>
  <collision>
    <origin rpy="0 0 0" xyz="-0.147314 -0.059696 -0.56"/>
    <geometry>
      <mesh filename="package://medibotv4_description/meshes/left_realsense_1.stl" scale="0.001 0.001 0.001"/>
    </geometry>
  </collision>
</link>

<link name="right_realsense_1">
  <inertial>
    <origin rpy="0 0 0" xyz="0.0026692640594299655 -0.0011190896800007816 5.551115123125783e-16"/>
    <mass value="0.04923710067597842"/>
    <inertia ixx="4.8e-05" ixy="-1.9e-05" ixz="0.0" iyy="1.1e-05" iyz="-0.0" izz="5.3e-05"/>
  </inertial>
  <visual>
    <origin rpy="0 0 0" xyz="-0.147314 0.059696 -0.56"/>
    <geometry>
      <mesh filename="package://medibotv4_description/meshes/right_realsense_1.stl" scale="0.001 0.001 0.001"/>
    </geometry>
    <material name="silver"/>
  </visual>
  <collision>
    <origin rpy="0 0 0" xyz="-0.147314 0.059696 -0.56"/>
    <geometry>
      <mesh filename="package://medibotv4_description/meshes/right_realsense_1.stl" scale="0.001 0.001 0.001"/>
    </geometry>
  </collision>
</link>

<link name="sonar_1">
  <inertial>
    <origin rpy="0 0 0" xyz="0.024761040929337313 1.4803902564637098e-17 0.03249999999999986"/>
    <mass value="2.6048925401122753"/>
    <inertia ixx="0.016776" ixy="-0.0" ixz="-0.0" iyy="0.0062" iyz="0.0" izz="0.021141"/>
  </inertial>
  <visual>
    <origin rpy="0 0 0" xyz="-0.08 -0.0 -0.69"/>
    <geometry>
      <mesh filename="package://medibotv4_description/meshes/sonar_1.stl" scale="0.001 0.001 0.001"/>
    </geometry>
    <material name="silver"/>
  </visual>
  <collision>
    <origin rpy="0 0 0" xyz="-0.08 -0.0 -0.69"/>
    <geometry>
      <mesh filename="package://medibotv4_description/meshes/sonar_1.stl" scale="0.001 0.001 0.001"/>
    </geometry>
  </collision>
</link>

<link name="pan_servo_1">
  <inertial>
    <origin rpy="0 0 0" xyz="-0.0021812244512274467 -0.028563653527876792 0.05585888345427237"/>
    <mass value="11.218433692744027"/>
    <inertia ixx="0.022969" ixy="0.000699" ixz="0.000791" iyy="0.022195" iyz="0.000526" izz="0.028495"/>
  </inertial>
  <visual>
    <origin rpy="0 0 0" xyz="-0.05 -0.0 -1.06"/>
    <geometry>
      <mesh filename="package://medibotv4_description/meshes/pan_servo_1.stl" scale="0.001 0.001 0.001"/>
    </geometry>
    <material name="silver"/>
  </visual>
  <collision>
    <origin rpy="0 0 0" xyz="-0.05 -0.0 -1.06"/>
    <geometry>
      <mesh filename="package://medibotv4_description/meshes/pan_servo_1.stl" scale="0.001 0.001 0.001"/>
    </geometry>
  </collision>
</link>

<link name="pan_tilt_mount_1">
  <inertial>
    <origin rpy="0 0 0" xyz="-0.001000621165341782 0.007999999999999986 0.09809881978571133"/>
    <mass value="3.0191586385796634"/>
    <inertia ixx="0.010238" ixy="0.0" ixz="0.000149" iyy="0.014175" iyz="-0.0" izz="0.004065"/>
  </inertial>
  <visual>
    <origin rpy="0 0 0" xyz="-0.05 -0.035 -1.07"/>
    <geometry>
      <mesh filename="package://medibotv4_description/meshes/pan_tilt_mount_1.stl" scale="0.001 0.001 0.001"/>
    </geometry>
    <material name="silver"/>
  </visual>
  <collision>
    <origin rpy="0 0 0" xyz="-0.05 -0.035 -1.07"/>
    <geometry>
      <mesh filename="package://medibotv4_description/meshes/pan_tilt_mount_1.stl" scale="0.001 0.001 0.001"/>
    </geometry>
  </collision>
</link>

<link name="tilt_servo_1">
  <inertial>
    <origin rpy="0 0 0" xyz="0.00024389797280190834 0.049434156703140976 -0.062402440810886306"/>
    <mass value="12.386466361420336"/>
    <inertia ixx="0.026619" ixy="0.000174" ixz="-3e-05" iyy="0.032047" iyz="6.9e-05" izz="0.026681"/>
  </inertial>
  <visual>
    <origin rpy="0 0 0" xyz="-0.05 -0.051 -1.27"/>
    <geometry>
      <mesh filename="package://medibotv4_description/meshes/tilt_servo_1.stl" scale="0.001 0.001 0.001"/>
    </geometry>
    <material name="silver"/>
  </visual>
  <collision>
    <origin rpy="0 0 0" xyz="-0.05 -0.051 -1.27"/>
    <geometry>
      <mesh filename="package://medibotv4_description/meshes/tilt_servo_1.stl" scale="0.001 0.001 0.001"/>
    </geometry>
  </collision>
</link>

<link name="mount_1">
  <inertial>
    <origin rpy="0 0 0" xyz="0.05211693226193341 -0.034112870741250065 0.12346040518414458"/>
    <mass value="4.256755717545082"/>
    <inertia ixx="0.07455" ixy="0.000197" ixz="-0.010024" iyy="0.077725" iyz="0.000466" izz="0.004427"/>
  </inertial>
  <visual>
    <origin rpy="0 0 0" xyz="-0.075 -0.035 -1.2175"/>
    <geometry>
      <mesh filename="package://medibotv4_description/meshes/mount_1.stl" scale="0.001 0.001 0.001"/>
    </geometry>
    <material name="silver"/>
  </visual>
  <collision>
    <origin rpy="0 0 0" xyz="-0.075 -0.035 -1.2175"/>
    <geometry>
      <mesh filename="package://medibotv4_description/meshes/mount_1.stl" scale="0.001 0.001 0.001"/>
    </geometry>
  </collision>
</link>

<link name="monitor_1">
  <inertial>
    <origin rpy="0 0 0" xyz="0.010000010577328328 -1.1068901035776004e-16 2.407478818522435e-07"/>
    <mass value="3.7546879999999994"/>
    <inertia ixx="0.141427" ixy="0.0" ixz="0.0" iyy="0.105382" iyz="-0.0" izz="0.036295"/>
  </inertial>
  <visual>
    <origin rpy="0 0 0" xyz="-0.1475 0.0 -1.217519"/>
    <geometry>
      <mesh filename="package://medibotv4_description/meshes/monitor_1.stl" scale="0.001 0.001 0.001"/>
    </geometry>
    <material name="silver"/>
  </visual>
  <collision>
    <origin rpy="0 0 0" xyz="-0.1475 0.0 -1.217519"/>
    <geometry>
      <mesh filename="package://medibotv4_description/meshes/monitor_1.stl" scale="0.001 0.001 0.001"/>
    </geometry>
  </collision>
</link>

<link name="camera_housing_1">
  <inertial>
    <origin rpy="0 0 0" xyz="0.0074877939399487226 1.823328231606211e-17 -0.009962494459304638"/>
    <mass value="0.19827705055401032"/>
    <inertia ixx="0.000178" ixy="-0.0" ixz="-4.9e-05" iyy="0.000123" iyz="0.0" izz="0.000169"/>
  </inertial>
  <visual>
    <origin rpy="0 0 0" xyz="-0.192857 -0.0 -1.561149"/>
    <geometry>
      <mesh filename="package://medibotv4_description/meshes/camera_housing_1.stl" scale="0.001 0.001 0.001"/>
    </geometry>
    <material name="silver"/>
  </visual>
  <collision>
    <origin rpy="0 0 0" xyz="-0.192857 -0.0 -1.561149"/>
    <geometry>
      <mesh filename="package://medibotv4_description/meshes/camera_housing_1.stl" scale="0.001 0.001 0.001"/>
    </geometry>
  </collision>
</link>

<link name="camera_1">
  <inertial>
    <origin rpy="0 0 0" xyz="0.0074999594047501505 -2.958887009148109e-07 -0.005624916158602389"/>
    <mass value="0.04663301595172273"/>
    <inertia ixx="1e-05" ixy="-0.0" ixz="-2e-06" iyy="8e-06" iyz="-0.0" izz="9e-06"/>
  </inertial>
  <visual>
    <origin rpy="0 0 0" xyz="-0.217785 -8e-06 -1.549013"/>
    <geometry>
      <mesh filename="package://medibotv4_description/meshes/camera_1.stl" scale="0.001 0.001 0.001"/>
    </geometry>
    <material name="silver"/>
  </visual>
  <collision>
    <origin rpy="0 0 0" xyz="-0.217785 -8e-06 -1.549013"/>
    <geometry>
      <mesh filename="package://medibotv4_description/meshes/camera_1.stl" scale="0.001 0.001 0.001"/>
    </geometry>
  </collision>
</link>

<link name="caster_1">
  <inertial>
    <origin rpy="0 0 0" xyz="0.0 -1.0052123437711852e-17 -0.01125000000000002"/>
    <mass value="0.4439070419522379"/>
    <inertia ixx="0.000104" ixy="0.0" ixz="-0.0" iyy="0.000104" iyz="-0.0" izz="0.00016"/>
  </inertial>
  <visual>
    <origin rpy="0 0 0" xyz="-0.2885 -0.0 -0.03"/>
    <geometry>
      <mesh filename="package://medibotv4_description/meshes/caster_1.stl" scale="0.001 0.001 0.001"/>
    </geometry>
    <material name="silver"/>
  </visual>
  <collision>
    <origin rpy="0 0 0" xyz="-0.2885 -0.0 -0.03"/>
    <geometry>
      <mesh filename="package://medibotv4_description/meshes/caster_1.stl" scale="0.001 0.001 0.001"/>
    </geometry>
  </collision>
</link>

<joint name="left_motor_joint" type="fixed">
  <origin rpy="0 0 0" xyz="-0.0535 0.1535 0.2145"/>
  <parent link="base_link"/>
  <child link="left_motor_1"/>
</joint>

<joint name="right_motor_joint" type="fixed">
  <origin rpy="0 0 0" xyz="-0.0535 -0.1535 0.2145"/>
  <parent link="base_link"/>
  <child link="right_motor_1"/>
</joint>

<joint name="left_wheel_joint" type="continuous">
  <origin rpy="0 0 0" xyz="0.036 0.1255 -0.0545"/>
  <parent link="left_motor_1"/>
  <child link="left_wheel_1"/>
  <axis xyz="-0.0 1.0 0.0"/>
</joint>

<joint name="right_wheel_joint" type="continuous">
  <origin rpy="0 0 0" xyz="0.036 -0.1255 -0.0545"/>
  <parent link="right_motor_1"/>
  <child link="right_wheel_1"/>
  <axis xyz="-0.0 1.0 0.0"/>
</joint>

<joint name="bottom_panel_joint" type="fixed">
  <origin rpy="0 0 0" xyz="0.0 -0.195 0.06"/>
  <parent link="base_link"/>
  <child link="bottom_panel_1"/>
</joint>

<joint name="circuit_panel_joint" type="fixed">
  <origin rpy="0 0 0" xyz="-0.2 0.0 0.35"/>
  <parent link="base_link"/>
  <child link="circuit_panel_1"/>
</joint>

<joint name="cicuit_housing_joint" type="fixed">
  <origin rpy="0 0 0" xyz="0.0 0.0 0.005"/>
  <parent link="circuit_panel_1"/>
  <child link="circuit_housing_1"/>
</joint>

<joint name="stand_joint" type="fixed">
  <origin rpy="0 0 0" xyz="0.08 0.195 0.005"/>
  <parent link="bottom_panel_1"/>
  <child link="stand_1"/>
</joint>

<joint name="body_joint" type="fixed">
  <origin rpy="0 0 0" xyz="-0.2 0.0 0.03"/>
  <parent link="base_link"/>
  <child link="body_1"/>
</joint>

<joint name="lidar_joint" type="fixed">
  <origin rpy="0 0 0" xyz="0.526625 0.0 0.195"/>
  <parent link="body_1"/>
  <child link="lidar_1"/>
</joint>

<joint name="top_panel_joint" type="fixed">
  <origin rpy="0 0 0" xyz="0.566625 -0.0 0.44"/>
  <parent link="body_1"/>
  <child link="top_panel_1"/>
</joint>

<joint name="realsense_housing_joint" type="fixed">
  <origin rpy="0 0 0" xyz="-0.195484 0.0 0.05"/>
  <parent link="top_panel_1"/>
  <child link="realsense_housing_1"/>
</joint>

<joint name="left_realsense_joint" type="fixed">
  <origin rpy="0 0 0" xyz="-0.023827 0.059696 0.04"/>
  <parent link="realsense_housing_1"/>
  <child link="left_realsense_1"/>
</joint>

<joint name="right_realsense_joint" type="fixed">
  <origin rpy="0 0 0" xyz="-0.023827 -0.059696 0.04"/>
  <parent link="realsense_housing_1"/>
  <child link="right_realsense_1"/>
</joint>

<joint name="sonar_joint" type="fixed">
  <origin rpy="0 0 0" xyz="0.0 0.0 0.625"/>
  <parent link="stand_1"/>
  <child link="sonar_1"/>
</joint>

<joint name="pan_servo_joint" type="continuous">
  <origin rpy="0 0 0" xyz="-0.03 0.0 0.995"/>
  <parent link="stand_1"/>
  <child link="pan_servo_1"/>
  <axis xyz="0.0 0.0 1.0"/>
</joint>

<joint name="pan_mount_joint" type="fixed">
  <origin rpy="0 0 0" xyz="0.0 0.035 0.01"/>
  <parent link="pan_servo_1"/>
  <child link="pan_tilt_mount_1"/>
</joint>

<joint name="tilt_mount_joint" type="fixed">
  <origin rpy="0 0 0" xyz="0.0 0.016 0.2"/>
  <parent link="pan_tilt_mount_1"/>
  <child link="tilt_servo_1"/>
</joint>

<joint name="tilt_servo_joint" type="continuous">
  <origin rpy="0 0 0" xyz="0.025 -0.016 -0.0525"/>
  <parent link="tilt_servo_1"/>
  <child link="mount_1"/>
  <axis xyz="0.0 -1.0 0.0"/>
</joint>

<joint name="monitor_joint" type="fixed">
  <origin rpy="0 0 0" xyz="0.0725 -0.035 1.9e-05"/>
  <parent link="mount_1"/>
  <child link="monitor_1"/>
</joint>

<joint name="camera_housing_joint" type="fixed">
  <origin rpy="0 0 0" xyz="0.117857 -0.035 0.343649"/>
  <parent link="mount_1"/>
  <child link="camera_housing_1"/>
</joint>

<joint name="camera_joint" type="fixed">
  <origin rpy="0 0 0" xyz="0.024928 8e-06 -0.012136"/>
  <parent link="camera_housing_1"/>
  <child link="camera_1"/>
</joint>

<joint name="caster_joint" type="fixed">
  <origin rpy="0 0 0" xyz="0.2885 0.0 0.03"/>
  <parent link="base_link"/>
  <child link="caster_1"/>
</joint>

</robot>
